<?xml version="1.0" ?>
<robot name="master" xmlns:xacro="http://www.ros.org/wiki/xacro">

  <!-- Macros -->
  <xacro:include filename="$(find dvrk_model)/model/common.urdf.xacro"/>

  <link name="world"/>
  <joint name="setup_joint" type="fixed">
    <parent link="world"/>
    <child link="ecm_setup_link"/>
    <origin rpy="0 0 0" xyz="0 0 1"/>
  </joint>
  <link name="ecm_setup_link">
    <visual>
      <origin rpy="0 0 0" xyz="0 0 0"/>
      <geometry>
        <mesh filename="package://dvrk_model/meshes/ecm/ecm_base_link.STL"/>
      </geometry>
      <material name="DaVinciWhite">
        <color rgba="${DaVinciWhite}"/>
      </material>
    </visual>
    <collision>
      <origin rpy="0 0 0" xyz="0 0 0"/>
      <geometry>
        <mesh filename="package://dvrk_model/meshes/ecm/ecm_base_link.STL"/>
      </geometry>
    </collision>
    <inertial>
      <origin rpy="0 0 0" xyz="0 0 0"/>
      <mass value=".9"/>
      <inertia ixx="9.0" ixy="0.0" ixz="0.0" iyy="9.0" iyz="0.0" izz="9.0"/>
    </inertial>
  </link>



  <joint name="ecm_base_joint" type="fixed">
    <parent link="ecm_setup_link"/>
    <child link="ecm_base_link"/>
    <origin rpy="-0.870463703366 0 -1.5707963267948966" xyz="0.92717 0 -0.12728"/>
  </joint>
  <link name="ecm_base_link"></link>


  <joint name="ecm_yaw_joint" type="revolute">
    <parent link="ecm_base_link"/>
    <child link="ecm_yaw_link"/>
    <origin rpy="${PI/2} ${-PI/2} 0" xyz="0 0 0"/>
    <axis xyz="0 0 1"/>
    <limit effort="50.0" lower="${-PI/2}" upper="${PI/2}" velocity="2"/>
    <joint_properties damping="1.0" friction="0.0"/>
  </joint>
  <link name="ecm_yaw_link">
    <visual>
      <origin rpy="-1.5707963267948966 0 -1.5707963267948966" xyz="0 0 0"/>
      <geometry>
        <mesh filename="package://dvrk_model/meshes/ecm/ecm_yaw_link.STL"/>
      </geometry>
      <material name="DaVinciBlue">
        <color rgba="${DaVinciBlue}"/>
      </material>
    </visual>
    <collision>
      <origin rpy="-1.5707963267948966 0 -1.5707963267948966" xyz="0 0 0"/>
      <geometry>
        <mesh filename="package://dvrk_model/meshes/ecm/ecm_yaw_link.STL"/>
      </geometry>
    </collision>
    <inertial>
      <origin rpy="-1.5707963267948966 0 -1.5707963267948966" xyz="0 0 0"/>
      <mass value=".9"/>
      <inertia ixx="9.0" ixy="0.0" ixz="0.0" iyy="9.0" iyz="0.0" izz="9.0"/>
    </inertial>
  </link>

  <joint name="ecm_pitch_joint_1" type="revolute">
    <parent link="ecm_yaw_link"/>
    <child link="ecm_pitch_link_1"/>
    <origin rpy="-1.570796326794896 -1.570796326794896 0" xyz="0 0 -0.225"/>
    <axis xyz="0 0 1"/>
    <limit effort="50.0" lower="${-PI/4}" upper="${PI*65/180}" velocity="2"/>
    <joint_properties damping="1.0" friction="0.0"/>
  </joint>
  <link name="ecm_pitch_link_1">
    <visual>
      <origin rpy="0 0 -0.198187435043" xyz="0 0 0"/>
      <geometry>
        <mesh filename="package://dvrk_model/meshes/ecm/ecm_pitch_link_1.STL"/>
      </geometry>
      <material name="DaVinciRed">
        <color rgba="${DaVinciRed}"/>
      </material>
    </visual>
    <collision>
      <origin rpy="0 0 -0.198187435043" xyz="0 0 0"/>
      <geometry>
        <mesh filename="package://dvrk_model/meshes/ecm/ecm_pitch_link_1.STL"/>
      </geometry>
    </collision>
    <inertial>
      <origin rpy="0 0 -0.198187435043" xyz="0 0 0"/>
      <mass value=".9"/>
      <inertia ixx="9.0" ixy="0.0" ixz="0.0" iyy="9.0" iyz="0.0" izz="9.0"/>
    </inertial>
  </link>


  <joint name="ecm_pitch_joint_2" type="revolute">
    <parent link="ecm_pitch_link_1"/>
    <child link="ecm_pitch_link_2"/>
    <origin rpy="0 0 0.198187435043" xyz="0.05512992 0.274519 0"/>
    <axis xyz="0 0 1"/>
    <limit effort="50.0" lower="-0.785398163397" upper="0.785398163397" velocity="2"/>
    <joint_properties damping="1.0" friction="0.0"/>
    <mimic joint="ecm_pitch_joint_1" multiplier="-1"/>
  </joint>
  <link name="ecm_pitch_link_2">
    <visual>
      <origin rpy="0 0 0" xyz="0 0 0"/>
      <geometry>
        <mesh filename="package://dvrk_model/meshes/ecm/ecm_pitch_link_2.STL"/>
      </geometry>
      <material name="DaVinciLightGray">
        <color rgba="${DaVinciLightGray}"/>
      </material>
    </visual>
    <collision>
      <origin rpy="0 0 0" xyz="0 0 0"/>
      <geometry>
        <mesh filename="package://dvrk_model/meshes/ecm/ecm_pitch_link_2.STL"/>
      </geometry>
    </collision>
    <inertial>
      <origin rpy="0 0 0" xyz="0 0 0"/>
      <mass value=".9"/>
      <inertia ixx="9.0" ixy="0.0" ixz="0.0" iyy="9.0" iyz="0.0" izz="9.0"/>
    </inertial>
  </link>

  <joint name="ecm_pitch_joint_3" type="revolute">
    <parent link="ecm_pitch_link_2"/>
    <child link="ecm_pitch_link_3"/>
    <origin rpy="0 0 0" xyz="-0.34 0 0"/>
    <axis xyz="0 0 1"/>
    <limit effort="50.0" lower="-0.785398163397" upper="0.785398163397" velocity="2"/>
    <joint_properties damping="1.0" friction="0.0"/>
    <mimic joint="ecm_pitch_joint_1" multiplier="1"/>
  </joint>
  <link name="ecm_pitch_link_3">
    <visual>
      <origin rpy="0 0 0" xyz="0 0 0"/>
      <geometry>
        <mesh filename="package://dvrk_model/meshes/ecm/ecm_pitch_link_3.STL"/>
      </geometry>
      <material name="DaVinciGreen">
        <color rgba="${DaVinciGreen}"/>
      </material>
    </visual>
    <collision>
      <origin rpy="0 0 0" xyz="0 0 0"/>
      <geometry>
        <mesh filename="package://dvrk_model/meshes/ecm/ecm_pitch_link_3.STL"/>
      </geometry>
    </collision>
    <inertial>
      <origin rpy="0 0 0" xyz="0 0 0"/>
      <mass value=".9"/>
      <inertia ixx="9.0" ixy="0.0" ixz="0.0" iyy="9.0" iyz="0.0" izz="9.0"/>
    </inertial>
  </link>





  <joint name="ecm_insertion_joint" type="prismatic">
    <parent link="ecm_pitch_link_3"/>
    <child link="ecm_insertion_link"/>
    <origin rpy="1.5707963267948966 0 0" xyz="-0.08805 0.14212563 0"/>
    <axis xyz="0 0 1"/>
    <limit effort="1000.0" lower="0" upper="0.235" velocity="2"/>
    <joint_properties damping="1.0" friction="0.0"/>
  </joint>
  <link name="ecm_insertion_link">
    <visual>
      <origin rpy="3.1415926 0 0" xyz="0 0 0"/>
      <geometry>
        <mesh filename="package://dvrk_model/meshes/ecm/ecm_insertion_link.STL"/>
      </geometry>
      <material name="DaVinciMedGray">
        <color rgba="${DaVinciMedGray}"/>
      </material>
    </visual>
    <collision>
      <origin rpy="3.1415926 0 0" xyz="0 0 0"/>
      <geometry>
        <mesh filename="package://dvrk_model/meshes/ecm/ecm_insertion_link.STL"/>
      </geometry>
    </collision>
    <inertial>
      <origin rpy="3.1415926 0 0" xyz="0 0 0"/>
      <mass value=".9"/>
      <inertia ixx="9.0" ixy="0.0" ixz="0.0" iyy="9.0" iyz="0.0" izz="9.0"/>
    </inertial>
  </link>



  <joint name="ecm_roll_joint" type="revolute">
    <parent link="ecm_insertion_link"/>
    <child link="ecm_roll_link"/>
    <!--fix z value-->
    <origin rpy="0 0 0" xyz="0 0 0.383"/>
    <axis xyz="0 0 1"/>
    <limit effort="50.0" lower="${-PI/2}" upper="${PI/2}" velocity="2"/>
    <joint_properties damping="1.0" friction="0.0"/>
  </joint>
  <link name="ecm_roll_link">
    <visual>
      <origin rpy="0 0 0" xyz="0 0 0"/>
      <geometry>
        <mesh filename="package://dvrk_model/meshes/ecm/ecm_roll_link.STL"/>
      </geometry>
      <material name="DaVinciDarkGray">
        <color rgba="${DaVinciDarkGray}"/>
      </material>
    </visual>
    <collision>
      <origin rpy="0 0 0" xyz="0 0 0"/>
      <geometry>
        <mesh filename="package://dvrk_model/meshes/ecm/ecm_roll_link.STL"/>
      </geometry>
    </collision>
    <inertial>
      <origin rpy="0 0 0" xyz="0 0 0"/>
      <mass value=".9"/>
      <inertia ixx="9.0" ixy="0.0" ixz="0.0" iyy="9.0" iyz="0.0" izz="9.0"/>
    </inertial>
  </link>
</robot>
