<?xml version="1.0" ?>
<robot name="mtm" xmlns:xacro="http://www.ros.org/wiki/xacro">
  <!-- Colors -->
  <xacro:include filename="$(find dvrk_model)/model/common.urdf.xacro"/>

  <!-- Macro for the da Vinci Master Console -->
  <xacro:macro name="master_console" params="prefix parent_link xyz rpy">
    <joint name="${prefix}base_fixed_joint" type="fixed">
      <parent link="${parent_link}"/>
      <child link="${prefix}master_base_link"/>
      <origin rpy="${rpy}" xyz="${xyz}"/>
    </joint>

    <link name="${prefix}master_base_link"/>

    <xacro:left_mtm prefix="${prefix}" parent_link="${prefix}master_base_link"/>
    <xacro:right_mtm prefix="${prefix}" parent_link="${prefix}master_base_link"/>
  </xacro:macro>

  <!-- Macros for left and right MTMs -->
  <xacro:macro name="mtm_left" params="prefix parent_link xyz rpy">
    <xacro:mtm 
        prefix="${prefix}left_"
        parent_link="${parent_link}"
        xyz="${xyz}" rpy="${rpy}"/>
    <xacro:mtm_platform_left prefix="${prefix}left_"/>    
  </xacro:macro>
  
  <xacro:macro name="mtm_right" params="prefix parent_link xyz rpy">
    <xacro:mtm 
      prefix="${prefix}right_"
      parent_link="${parent_link}"
      xyz="${xyz}" rpy="${rpy}"/>
    <xacro:mtm_platform_right prefix="${prefix}right_"/>
  </xacro:macro>

  <!-- Macro for da Vinci Master Tool Manipulator (MTM) -->
  <xacro:macro name="mtm" params="prefix parent_link xyz rpy">

    <!-- Joint 0: Fixed to World-->
    <joint name="${prefix}fixed_joint" type="fixed">
      <parent link="${parent_link}"/>
      <child link="${prefix}top_panel"/>
      <origin rpy="${rpy}" xyz="${xyz}"/>
    </joint>

    <link name="${prefix}top_panel">
      <visual>
        <origin rpy="0 0 0" xyz="0 0 0.19037"/>
        <geometry>
          <mesh filename="package://dvrk_model/meshes/mtm/Top Panel.dae"/>
        </geometry>
      </visual>
      <collision>
        <origin rpy="0 0 0" xyz="0 0 0.19037"/>
        <geometry>
          <mesh filename="package://dvrk_model/meshes/mtm/Top Panel.STL"/>
        </geometry>
      </collision>
      <inertial>
        <origin xyz="0 0 0" rpy="0 0 0"/>
        <mass value=".9"/>
        <inertia ixx="9.0" ixy="0.0" ixz="0.0" 
                           iyy="9.0" iyz="0.0" 
                                     izz="9.0"/>
      </inertial> 
    </link>

    <!-- Joint 1: Outer Yaw -->
    <joint name="${prefix}outer_yaw_joint" type="revolute">
      <parent link="${prefix}top_panel"/>
      <child link="${prefix}outer_yaw_link"/>
      <origin rpy="0 0 ${PI/2}" xyz="0 0 0"/>
      <axis xyz="0 0 1"/>
      <!--rotates about z axis-->
      <!--limit effort and velocity picked arbitrarily check-->
      <limit effort="50.0" lower="${-75/180*PI}" upper="${PI/4}" velocity="2"/>
      <joint_properties damping="1.0" friction="0.0"/>
    </joint>

    <link name="${prefix}outer_yaw_link">
      <visual>
        <origin rpy="0 0 0" xyz="0.025 0 0.19037"/>
        <geometry>
          <mesh filename="package://dvrk_model/meshes/mtm/OutPitch_Shoulder.dae"/>
        </geometry>
      </visual>
      <collision>
        <origin rpy="0 0 0" xyz="0.025 0 0.19037"/>
        <geometry>
          <mesh filename="package://dvrk_model/meshes/mtm/OutPitch_Shoulder.STL"/>
        </geometry>
      </collision>
      <inertial>
        <mass value="1"/>
        <inertia ixx="10.0" ixy="0.0" ixz="0.0" iyy="10.0" iyz="0.0" izz="10.0"/>
      </inertial>
    </link>


    <!-- Joint 2: Shoulder Pitch -->
    <joint name="${prefix}shoulder_pitch_joint" type="revolute">
      <parent link="${prefix}outer_yaw_link"/>
      <child link="${prefix}back_parallel_link"/>  <!-- xyz= 0 0 -.19037-->
      <origin rpy="${-PI/2} ${-PI/2} 0" xyz="0 0 0"/>
      <axis xyz="0 0 1"/>
      <!--limit effort and velocity picked arbitrarily check-->
      <limit effort="100.0" lower="${-PI/4}" upper="${PI/4}" velocity="10"/>
      <joint_properties damping="1.0" friction="0.0"/>
    </joint>

    <link name="${prefix}back_parallel_link">
      <visual>
        <geometry>
          <mesh filename="package://dvrk_model/meshes/mtm/ArmParallel.dae"/>
        </geometry>
      </visual>
      <collision>
        <geometry>
          <mesh filename="package://dvrk_model/meshes/mtm/ArmParallel.STL"/>
        </geometry>
      </collision>
      <inertial>
        <mass value=".9"/>
        <inertia ixx="9.0" ixy="0.0" ixz="0.0" iyy="9.0" iyz="0.0" izz="9.0"/>
      </inertial>
    </link>

    <joint name="${prefix}shoulder_pitch_parallel_joint" type="revolute">
      <parent link="${prefix}outer_yaw_link"/>
      <child link="${prefix}top_parallel_link"/>
      <origin rpy="${-PI/2} ${-PI/2} 0" xyz="0 0 0"/>
      <axis xyz="0 0 1"/>
      <!--rotates about  x axis-->
      <!--limit effort and velocity picked arbitrarily check-->
      <limit effort="100.0" lower="${-PI/2}" upper="${PI/2}" velocity="10"/>
      <joint_properties damping="1.0" friction="0.0"/>
      <mimic joint="${prefix}shoulder_pitch_joint" multiplier="1"/>
    </joint>

    <link name="${prefix}top_parallel_link">
      <visual>
        <origin rpy="0 0 ${-PI/2}" xyz="0 0 0.065"/>
        <geometry>
          <mesh filename="package://dvrk_model/meshes/mtm/ArmParallel1.dae"/>
        </geometry>
      </visual>
      <collision>
        <origin rpy="0 0 0" xyz="0 0 0"/>
        <geometry>
          <mesh filename="package://dvrk_model/meshes/mtm/ArmParallel1.STL"/>
        </geometry>
      </collision>
      <inertial>
        <mass value=".5"/>
        <inertia ixx="5.0" ixy="0.0" ixz="0.0" iyy="5.0" iyz="0.0" izz="5.0"/>
      </inertial>
    </link>

    
    <!-- Joint 3: Elbow Pitch -->
    <joint name="${prefix}elbow_pitch_joint" type="revolute">
      <parent link="${prefix}back_parallel_link"/>
      <child link="${prefix}bottom_parallel_link"/>  <!-- xyz= -->
      <origin rpy="0 0 ${PI/2}" xyz="-0.2794 0 0"/>
      <axis xyz="0 0 1"/>
      <!--limit effort and velocity picked arbitrarily check-->
      <limit effort="100.0" lower="${-PI/4}" upper="${PI/4}" velocity="10"/>
      <joint_properties damping="1.0" friction="0.0"/>
    </joint>

    <link name="${prefix}bottom_parallel_link">
      <visual>
        <geometry>
          <mesh filename="package://dvrk_model/meshes/mtm/BottomArm.dae"/>
        </geometry>
      </visual>
      <collision>
        <geometry>
          <mesh filename="package://dvrk_model/meshes/mtm/BottomArm.STL"/>
        </geometry>
      </collision>
      <inertial>
        <mass value="0.8"/>
        <inertia ixx="0.1" ixy="0.0" ixz="0.0" 
                 iyy="0.1" iyz="0.0"
                 izz="0.1"/>
      </inertial>
    </link>

    <transmission name="tran1">
      <type>transmission_interface/SimpleTransmission</type>
      <joint name="${prefix}outer_yaw_joint"/>
      <actuator name="motor1">
        <hardwareInterface>EffortJointInterface</hardwareInterface>
        <mechanicalReduction>1</mechanicalReduction>
      </actuator>
    </transmission>
    <transmission name="tran2">
      <type>transmission_interface/SimpleTransmission</type>
      <joint name="${prefix}shoulder_pitch_joint"/>
      <actuator name="motor2">
        <hardwareInterface>EffortJointInterface</hardwareInterface>
        <mechanicalReduction>1</mechanicalReduction>
      </actuator>
    </transmission>
    <transmission name="tran3">
      <type>transmission_interface/SimpleTransmission</type>
      <joint name="${prefix}elbow_pitch_joint"/>
      <actuator name="motor3">
        <hardwareInterface>EffortJointInterface</hardwareInterface>
        <mechanicalReduction>1</mechanicalReduction>
      </actuator>
    </transmission>
    <gazebo>
      <plugin name="gazebo_ros_control" filename="libgazebo_ros_control.so">
        <robotNamespace>/mtm</robotNamespace>
      </plugin>
    </gazebo>

    <gazebo>
      <plugin name="force_torque_sensor" filename="libgazebo_ros_f3d.so" >
        <bodyName>${prefix}bottom_parallel_link</bodyName>
        <frameName>${prefix}bottom_parallel_link</frameName>
        <topicName>/force_torque_feedback</topicName>
        <alwaysOn>true</alwaysOn>
        <updateRate>100.0</updateRate>
      </plugin>
    </gazebo>
  </xacro:macro>


  <!-- Macro for dVRK MTM Platform Right -->
  <xacro:macro name="mtm_platform_right" params="prefix">
    <!-- Joint 4: Platform -->
    <joint name="${prefix}wrist_platform_joint" type="revolute">
      <parent link="${prefix}bottom_parallel_link"/>
      <child link="${prefix}wrist_platform_link"/>
      <origin rpy="${PI/2} 0 0" xyz="-0.3645 -0.1506 0.0"/>
      <axis xyz="0 0 1"/>
      <!--rotates about z axis-->
      <!--limit effort and velocity picked arbitrarily check-->
      <limit effort="100.0" lower="${-60/180*PI}" upper="${245/180*PI}" velocity="10"/>
      <joint_properties damping="1.0" friction="0.0"/>
    </joint>

    <link name="${prefix}wrist_platform_link">
      <visual>
        <geometry>
          <mesh filename="package://dvrk_model/meshes/mtm/WristPlatform.dae"/>
        </geometry>
      </visual>
      <collision>
        <geometry>
          <mesh filename="package://dvrk_model/meshes/mtm/WristPlatform.STL"/>
        </geometry>
      </collision>
      <inertial>
        <mass value="0.4"/>
        <inertia ixx="0.1" ixy="0.0" ixz="0.0" 
                 iyy="0.1" iyz="0.0"
                 izz="0.1"/>
      </inertial>
    </link>

    <!-- Joint 5: Wrist Pitch -->
    <joint name="${prefix}wrist_pitch_joint" type="revolute">
      <parent link="${prefix}wrist_platform_link"/>
      <child link="${prefix}wrist_pitch_link"/>   
      <origin rpy="${-PI/2} 0 0" xyz="0 0 0"/>
      <axis xyz="0 0 1"/>
      <!--limit effort and velocity picked arbitrarily check-->
      <limit effort="100.0" lower="${-PI/2}" upper="${PI}" velocity="10"/>
      <joint_properties damping="1.0" friction="0.0"/>
    </joint>

    <link name="${prefix}wrist_pitch_link">
      <visual>        <!-- defined from CAD file (increased in the y dir by .005-->
        <geometry>
          <mesh filename="package://dvrk_model/meshes/mtm/WristPitch.dae"/>
        </geometry>
      </visual>
      <collision>        <!-- defined from CAD file (increased in the y dir by .005-->
        <geometry>
          <mesh filename="package://dvrk_model/meshes/mtm/WristPitch.STL"/>
        </geometry>
      </collision>
      <inertial>
        <mass value="0.2"/>
        <inertia ixx="0.1" ixy="0.0" ixz="0.0" 
                 iyy="0.1" iyz="0.0"
                 izz="0.1"/>
      </inertial>
    </link> 

    <!-- Joint 6: Wrist Yaw-->
    <joint name="${prefix}wrist_yaw_joint" type="revolute">
      <parent link="${prefix}wrist_pitch_link"/>
      <child link="${prefix}wrist_yaw_link"/>    <!--  defined from CAD file-->
      <origin rpy="${PI/2} ${-PI/2} 0" xyz="0 0 0"/>
      <axis xyz="0 0 1"/>
      <!--rotates about z axis-->
      <!--limit effort and velocity picked arbitrarily check-->
      <limit effort="100.0"  lower="${-PI/4}" upper="${PI/4}" velocity="10"/>
      <joint_properties damping="1.0" friction="0.0"/>
    </joint>

    <link name="${prefix}wrist_yaw_link">
      <visual>
        <geometry>
          <mesh filename="package://dvrk_model/meshes/mtm/WristYaw.dae"/>
        </geometry>
      </visual>
      <collision>
        <geometry>
          <mesh filename="package://dvrk_model/meshes/mtm/WristYaw.STL"/>
        </geometry>
      </collision>
      <inertial>
        <mass value="0.2"/>
        <inertia ixx="0.1" ixy="0.0" ixz="0.0" 
                 iyy="0.1" iyz="0.0"
                 izz="0.1"/>
      </inertial>
    </link>


    <!-- Joint 7: Wrist Roll -->
    <joint name="${prefix}wrist_roll_joint" type="revolute">
      <parent link="${prefix}wrist_yaw_link"/>
      <child link="${prefix}wrist_roll_link"/>  <!-- -.039 & .055 defined from CAD file-->
      <!-- <origin rpy="${-PI/2} ${PI/2} 0" xyz="0 -.039 0"/> -->
      <origin rpy="0 ${-PI/2} ${PI/2}" xyz="0 0 0"/>
      <axis xyz="0 0 1"/>
      <!--limit effort and velocity picked arbitrarily check-->
      <limit effort="100.0" lower="${-1.5*PI}" upper="${1.5*PI}" velocity="10"/>
      <joint_properties damping="1.0" friction="0.0"/>
    </joint>

    <link name="${prefix}wrist_roll_link">
      <visual>
        <origin rpy="${PI} 0 0" xyz="0 0 0.039"/>
        <geometry>
          <mesh filename="package://dvrk_model/meshes/mtm/WristRoll.dae"/>
        </geometry>
      </visual>
      <collision>
        <origin rpy="${PI} 0 0" xyz="0 0 0.039"/>
        <geometry>
          <mesh filename="package://dvrk_model/meshes/mtm/WristRoll.STL"/>
        </geometry>
      </collision>
      <inertial>
        <mass value="0.1"/>
        <inertia ixx="0.1" ixy="0.0" ixz="0.0" 
                 iyy="0.1" iyz="0.0"
                 izz="0.1"/>
      </inertial>
    </link>

    <transmission name="tran4">
      <type>transmission_interface/SimpleTransmission</type>
      <joint name="${prefix}wrist_platform_joint"/>
      <actuator name="motor4">
        <hardwareInterface>EffortJointInterface</hardwareInterface>
        <mechanicalReduction>1</mechanicalReduction>
      </actuator>
    </transmission>
    <transmission name="tran5">
      <type>transmission_interface/SimpleTransmission</type>
      <joint name="${prefix}wrist_pitch_joint"/>
      <actuator name="motor5">
        <hardwareInterface>EffortJointInterface</hardwareInterface>
        <mechanicalReduction>1</mechanicalReduction>
      </actuator>
    </transmission>
    <transmission name="tran6">
      <type>transmission_interface/SimpleTransmission</type>
      <joint name="${prefix}wrist_yaw_joint"/>
      <actuator name="motor6">
        <hardwareInterface>EffortJointInterface</hardwareInterface>
        <mechanicalReduction>1</mechanicalReduction>
      </actuator>
    </transmission>
    <transmission name="tran7">
      <type>transmission_interface/SimpleTransmission</type>
      <joint name="${prefix}wrist_roll_joint"/>
      <actuator name="motor7">
        <hardwareInterface>EffortJointInterface</hardwareInterface>
        <mechanicalReduction>1</mechanicalReduction>
      </actuator>
    </transmission>
    
  </xacro:macro>


  <!-- Macro for dVRK MTM Platform Left -->
  <xacro:macro name="mtm_platform_left" params="prefix">
    <!-- Joint 4: Platform -->
    <joint name="${prefix}wrist_platform_joint" type="revolute">
      <parent link="${prefix}bottom_parallel_link"/>
      <child link="${prefix}wrist_platform_link"/>
      <origin rpy="${PI/2} 0 0" xyz="-0.3645 -0.1506 0.0"/>
      <axis xyz="0 0 1"/>
      <!--rotates about z axis-->
      <!--limit effort and velocity picked arbitrarily check-->
      <limit effort="100.0" lower="${-60/180*PI}" upper="${245/180*PI}" velocity="10"/>
      <joint_properties damping="1.0" friction="0.0"/>
    </joint>

    <link name="${prefix}wrist_platform_link">
      <visual>
        <origin rpy="0 0 ${PI}" xyz="0.0 0.0 0.0"/>
        <geometry>
          <mesh filename="package://dvrk_model/meshes/mtm/WristPlatform.dae"/>
        </geometry>
      </visual>
      <collision>
        <origin rpy="0 0 ${PI}" xyz="0.0 0.0 0.0"/>
        <geometry>
          <mesh filename="package://dvrk_model/meshes/mtm/WristPlatform.STL"/>
        </geometry>
      </collision>
      <inertial>
        <mass value="0.4"/>
        <inertia ixx="0.1" ixy="0.0" ixz="0.0" 
                 iyy="0.1" iyz="0.0"
                 izz="0.1"/>
      </inertial>
    </link>

    <!-- Joint 5: Wrist Pitch -->
    <joint name="${prefix}wrist_pitch_joint" type="revolute">
      <parent link="${prefix}wrist_platform_link"/>
      <child link="${prefix}wrist_pitch_link"/>   
      <origin rpy="${-PI/2} 0 0" xyz="0 0 0"/>
      <axis xyz="0 0 1"/>
      <!--limit effort and velocity picked arbitrarily check-->
      <limit effort="100.0" lower="${-PI/2}" upper="${PI}" velocity="10"/>
      <joint_properties damping="1.0" friction="0.0"/>
    </joint>

    <link name="${prefix}wrist_pitch_link">
      <visual>        <!-- defined from CAD file (increased in the y dir by .005-->
        <origin rpy="0 ${PI} 0" xyz="0.0 0.0 0.0"/>
        <geometry>
          <mesh filename="package://dvrk_model/meshes/mtm/WristPitch.dae"/>
        </geometry>
      </visual>
      <collision>        <!-- defined from CAD file (increased in the y dir by .005-->
        <origin rpy="0 ${PI} 0" xyz="0.0 0.0 0.0"/>
        <geometry>
          <mesh filename="package://dvrk_model/meshes/mtm/WristPitch.STL"/>
        </geometry>
      </collision>
      <inertial>
        <mass value="0.2"/>
        <inertia ixx="0.1" ixy="0.0" ixz="0.0" 
                 iyy="0.1" iyz="0.0"
                 izz="0.1"/>
      </inertial>
    </link> 

    <!-- Joint 6: Wrist Yaw-->
    <joint name="${prefix}wrist_yaw_joint" type="revolute">
      <parent link="${prefix}wrist_pitch_link"/>
      <child link="${prefix}wrist_yaw_link"/>    <!--  defined from CAD file-->
      <origin rpy="${PI/2} ${-PI/2} 0" xyz="0 0 0"/>
      <axis xyz="0 0 1"/>
      <!--rotates about z axis-->
      <!--limit effort and velocity picked arbitrarily check-->
      <limit effort="100.0"  lower="${-PI/4}" upper="${PI/4}" velocity="10"/>
      <joint_properties damping="1.0" friction="0.0"/>
    </joint>

    <link name="${prefix}wrist_yaw_link">
      <visual>
        <geometry>
          <mesh filename="package://dvrk_model/meshes/mtm/WristYaw.dae"/>
        </geometry>
      </visual>
      <collision>
        <geometry>
          <mesh filename="package://dvrk_model/meshes/mtm/WristYaw.STL"/>
        </geometry>
      </collision>
      <inertial>
        <mass value="0.2"/>
        <inertia ixx="0.1" ixy="0.0" ixz="0.0" 
                 iyy="0.1" iyz="0.0"
                 izz="0.1"/>
      </inertial>
    </link>


    <!-- Joint 7: Wrist Roll -->
    <joint name="${prefix}wrist_roll_joint" type="revolute">
      <parent link="${prefix}wrist_yaw_link"/>
      <child link="${prefix}wrist_roll_link"/>  <!-- -.039 & .055 defined from CAD file-->
      <!-- <origin rpy="${-PI/2} ${PI/2} 0" xyz="0 -.039 0"/> -->
      <origin rpy="0 ${-PI/2} ${PI/2}" xyz="0 0 0"/>
      <axis xyz="0 0 1"/>
      <!--limit effort and velocity picked arbitrarily check-->
      <limit effort="100.0" lower="${-1.5*PI}" upper="${1.5*PI}" velocity="10"/>
      <joint_properties damping="1.0" friction="0.0"/>
    </joint>

    <link name="${prefix}wrist_roll_link">
      <visual>
        <origin rpy="${PI} 0 0" xyz="0 0 0.039"/>
        <geometry>
          <mesh filename="package://dvrk_model/meshes/mtm/WristRoll.dae"/>
        </geometry>
      </visual>
      <collision>
        <origin rpy="${PI} 0 0" xyz="0 0 0.039"/>
        <geometry>
          <mesh filename="package://dvrk_model/meshes/mtm/WristRoll.STL"/>
        </geometry>
      </collision>
      <inertial>
        <mass value="0.1"/>
        <inertia ixx="0.1" ixy="0.0" ixz="0.0" 
                 iyy="0.1" iyz="0.0"
                 izz="0.1"/>
      </inertial>
    </link>

    <transmission name="tran4">
      <type>transmission_interface/SimpleTransmission</type>
      <joint name="${prefix}wrist_platform_joint"/>
      <actuator name="motor4">
        <hardwareInterface>EffortJointInterface</hardwareInterface>
        <mechanicalReduction>1</mechanicalReduction>
      </actuator>
    </transmission>
    <transmission name="tran5">
      <type>transmission_interface/SimpleTransmission</type>
      <joint name="${prefix}wrist_pitch_joint"/>
      <actuator name="motor5">
        <hardwareInterface>EffortJointInterface</hardwareInterface>
        <mechanicalReduction>1</mechanicalReduction>
      </actuator>
    </transmission>
    <transmission name="tran6">
      <type>transmission_interface/SimpleTransmission</type>
      <joint name="${prefix}wrist_yaw_joint"/>
      <actuator name="motor6">
        <hardwareInterface>EffortJointInterface</hardwareInterface>
        <mechanicalReduction>1</mechanicalReduction>
      </actuator>
    </transmission>
    <transmission name="tran7">
      <type>transmission_interface/SimpleTransmission</type>
      <joint name="${prefix}wrist_roll_joint"/>
      <actuator name="motor7">
        <hardwareInterface>EffortJointInterface</hardwareInterface>
        <mechanicalReduction>1</mechanicalReduction>
      </actuator>
    </transmission>
    
  </xacro:macro>
  
</robot>


