<?xml version="1.0" encoding="utf-8"?>
<robot name="dvrk_psm" xmlns:xacro="http://www.ros.org/wiki/xacro">

  <!-- This file contains different tool urdf -->
  <xacro:include filename="$(find dvrk_model)/model/common.urdf.xacro"/>

  <!-- sca  -->
  <xacro:macro name="psm_tool_sca" params="prefix">
    
    <!-- joint 5: Outer wrist pitch joint -->
    <joint name="outer_wrist_pitch" type="revolute">
      <parent link="${prefix}tool_wrist_shaft_link"/>
      <child link="${prefix}tool_wrist_sca_link"/>
      <axis xyz="0 0 1"/>
      <origin rpy="-1.5708 -1.5708 0" xyz="0 0 0"/>
      <limit lower="-1.5707" upper="1.5707" velocity=".4" effort="1000"/>
    </joint>

    <!-- link 5: tool_wrist_sca_link -->
    <link name="${prefix}tool_wrist_sca_link">
      <visual>
        <!-- <origin rpy="0 3.1416 0" xyz="0 0 0"/> -->
        <origin rpy="1.5708 3.1416 0" xyz="0.0051 0.0032 0"/>
        <geometry>
          <mesh filename="package://dvrk_model/meshes/psm/tool_wrist_sca_link.dae"/> 
        </geometry>
      </visual>
    </link>

    <!-- joint 6: Outer wrist yaw joint -->
    <joint name="outer_wrist_yaw" type="revolute">
      <parent link="${prefix}tool_wrist_sca_link"/>
      <child link="${prefix}tool_wrist_sca_shaft_link"/>
      <axis xyz="0 0 1"/>
      <origin rpy="-1.5708 -1.5708 0" xyz="0.0091 0 0"/>
      <!-- +/- 80 deg -->
      <limit lower="-1.3963" upper="1.3963" velocity=".4" effort="1000"/>
    </joint>

    <!-- link 6: tool_wrist_sca_shaft_link -->
    <link name="${prefix}tool_wrist_sca_shaft_link">
      <visual>
        <origin rpy="0 0 0" xyz="0 -0.0002 -0.0025"/>
        <geometry>
          <mesh filename="package://dvrk_model/meshes/psm/tool_wrist_sca_shaft_link.dae"/> 
        </geometry>
      </visual>
    </link>
    
    <!-- joint 7-0: Outer open angle 1  -->
    <joint name="jaw" type="revolute">
      <parent link="${prefix}tool_wrist_sca_shaft_link"/>
      <child link="${prefix}tool_wrist_sca_ee_link_0"/>      
      <axis xyz="0 0 1"/>
      <origin rpy="0 0 0" xyz="0 0 0"/>
      <limit lower="0" upper="1.5707" velocity=".4" effort="1000"/>
    </joint>

    <!-- link 7-0: Outer open angle virtual -->
    <link name="${prefix}tool_wrist_sca_ee_link_0">
      <visual>
        <origin rpy="0 0 0" xyz="0 0 0"/>
        <geometry>          
          <box size="0 0 0" />
        </geometry>
      </visual>
    </link>

    <!-- joint 7-1: Outer open angle 1  -->
    <joint name="jaw_mimic_1" type="revolute">
      <parent link="${prefix}tool_wrist_sca_shaft_link"/>
      <child link="${prefix}tool_wrist_sca_ee_link_1"/>
      <axis xyz="0 0 1"/>
      <origin rpy="0 0 0" xyz="0 0 0"/>
      <limit lower="-1.5707" upper="1.5707" velocity=".4" effort="1000"/>
      <mimic joint="jaw" multiplier="0.5"/>
    </joint>

    <!-- link 7-1: Outer open angle link 1 -->
    <link name="${prefix}tool_wrist_sca_ee_link_1">
      <visual>
        <origin rpy="0 0 0" xyz="0 0 0"/>
        <geometry>
          <mesh filename="package://dvrk_model/meshes/psm/tool_wrist_sca_link_2.dae"/>
        </geometry>
      </visual>
    </link>

    <!-- joint 7-2: Outer open angle 2   -->
    <joint name="jaw_mimic_2" type="revolute">
      <parent link="${prefix}tool_wrist_sca_shaft_link"/>
      <child link="${prefix}tool_wrist_sca_ee_link_2"/>
      <axis xyz="0 0 1"/>
      <origin rpy="0 0 0" xyz="0 0 0"/>
      <limit lower="-1.5707" upper="1.5707" velocity=".4" effort="1000"/>
      <mimic joint="jaw" multiplier="-0.5"/>
    </joint>

    <!-- link 7-2: Outer open angle link 2 -->
    <link name="${prefix}tool_wrist_sca_ee_link_2">
      <visual>
        <origin rpy="0 3.1516 0" xyz="0 0 0"/>
        <geometry>
          <mesh filename="package://dvrk_model/meshes/psm/tool_wrist_sca_link_2.dae"/>
        </geometry>
      </visual>
    </link>

    <!-- tool tip -->
    <joint name="tool_tip" type="fixed">
      <parent link="${prefix}tool_wrist_sca_shaft_link"/>
      <child link="${prefix}tool_tip_link"/>
      <origin rpy="0 ${PI/2} ${PI/2}" xyz="0 0.0102 0"/>
    </joint>
    <link name="${prefix}tool_tip_link"/>
    
  </xacro:macro>
  
</robot>
