<?xml version="1.0" encoding="utf-8"?>
<robot name="dvrk_psm" xmlns:xacro="http://www.ros.org/wiki/xacro">

  <xacro:macro name="psm_tool_caudier" params="prefix">
    
    <!-- joint 5: Outer wrist pitch joint -->
    <joint name="${prefix}outer_wrist_pitch_joint" type="revolute">
      <parent link="${prefix}tool_wrist_shaft_link"/>
      <child link="${prefix}tool_wrist_caudier_link"/>
      <axis xyz="0 0 1"/>
      <origin rpy="-1.5708 -1.5708 0" xyz="0 0 0"/>
      <limit lower="-1.5707" upper="1.5707" velocity=".4" effort="1000"/>
    </joint>
    
    <!-- link 5: tool_wrist_caudier_link -->
    <link name="${prefix}tool_wrist_caudier_link">
      <visual>
        <origin rpy="0.00 -1.5708 0.0" xyz="-0.0024 0.00 0.000"/>
        <geometry>
          <mesh filename="package://dvrk_model/meshes/psm/tool_wrist_caudier_link_1.stl"/>
        </geometry>
        <material name="gray"><color rgba="0.5 0.5 0.9 1.0"/></material>
      </visual>
      <collision>
        <origin rpy="0.00 -1.5708 0.0" xyz="-0.0024 0.00 0.000"/>
        <geometry>
          <mesh filename="package://dvrk_model/meshes/psm/tool_wrist_caudier_link_1.stl"/>
        </geometry>
      </collision>
    </link>

    <!-- joint 6: Tool wrist yaw joint -->
    <joint name="${prefix}outer_wrist_yaw_joint" type="revolute">
      <parent link="${prefix}tool_wrist_caudier_link"/>
      <child link="${prefix}tool_wrist_caudier_link_shaft"/>
      <axis xyz="0 0 1"/>
      <origin rpy="0.00 -1.5708 -1.5708" xyz="0.0091 0 0"/>
      <limit lower="-1.5707" upper="1.5707" velocity=".4" effort="1000"/>
    </joint>

    <!-- link 6: tool_wrist_caudier_link_shaft -->
    <link name="${prefix}tool_wrist_caudier_link_shaft">
      <visual>
        <origin rpy="0.00 1.5708 0.0" xyz="0.0 -0.0002 0.000"/>
        <geometry>
          <mesh filename="package://dvrk_model/meshes/psm/tool_wrist_caudier_link_1_shaft.stl"/>
        </geometry>
        <material name="gray"><color rgba="0.5 0.5 0.9 1.0"/></material>
      </visual>
      <collision>
        <origin rpy="0.00 1.5708 0.0" xyz="0.0 0.00 0.000"/>
        <geometry>
          <mesh filename="package://dvrk_model/meshes/psm/tool_wrist_caudier_link_1_shaft.stl"/>
        </geometry>
      </collision>
    </link>
    
    <!-- joint 6-1: Outer open angle 1 -->
    <joint name="${prefix}outer_wrist_open_angle_joint" type="revolute">
      <parent link="${prefix}tool_wrist_caudier_link_shaft"/>
      <child link="${prefix}tool_wrist_caudier_link_2_left"/>
      <axis xyz="0 0 1"/>
      <origin rpy="0 0 0" xyz="0 0 0"/>
      <limit lower="0" upper="1.5707" velocity=".4" effort="1000"/>
    </joint>

    <!-- link 6-1: Outer open angle link 1 -->
    <link name="${prefix}tool_wrist_caudier_link_2_left">
      <visual>
        <origin rpy="0.0 0 0.0" xyz="0 0 0.00195"/>
        <geometry>
          <mesh filename="package://dvrk_model/meshes/psm/tool_wrist_caudier_link_2_left.stl"/>
        </geometry>
      </visual>
      <collision>
        <origin rpy="0.0 0 0.0" xyz="0 0 0.00195"/>
        <geometry>
          <mesh filename="package://dvrk_model/meshes/psm/tool_wrist_caudier_link_2_left.stl"/>
        </geometry>
      </collision>
    </link>

    <!-- joint 6-2: Outer open angle 2  -->
    <joint name="${prefix}outer_wrist_open_angle_joint_mimic" type="revolute">
      <parent link="${prefix}tool_wrist_caudier_link_shaft"/>
      <child link="${prefix}tool_wrist_caudier_link_2_right"/>
      <axis xyz="0 0 1"/>
      <origin rpy="3.1415926 0 0" xyz="0 0 0"/>
      <limit lower="0" upper="1.5707" velocity=".4" effort="1000"/>
      <mimic joint="${prefix}outer_wrist_open_angle_joint" multiplier="1"/>
    </joint>

    <!-- link 6-2: Outer open angle link 2 -->
    <link name="${prefix}tool_wrist_caudier_link_2_right">
      <visual>
        <origin rpy="0 0 -3.1415926" xyz="0 0 0.00195"/>
        <geometry>
          <mesh filename="package://dvrk_model/meshes/psm/tool_wrist_caudier_link_2_right.stl"/>
        </geometry>
      </visual>
      <collision>
        <origin rpy="0 0 -3.1415926" xyz="0 0 0.00195"/>
        <geometry>
          <mesh filename="package://dvrk_model/meshes/psm/tool_wrist_caudier_link_2_right.stl"/>
        </geometry>
      </collision>
    </link>

  </xacro:macro>

</robot>


