<?xml version="1.0" ?>
<!-- =================================================================================== -->
<!-- |    This document was autogenerated by xacro from /opt/ros/groovy/stacks/robot_model_tutorials/DaVinci_MasterC.urdf.xacro | -->
<!-- |    EDITING THIS FILE BY HAND IS NOT RECOMMENDED                                 | -->
<!-- =================================================================================== -->
<!--not sure about xmlns:xacro path -->
<robot name="DaVinci Robot" >
  <!-- default_inertial -->
  <!-- Origins -->


  <link name="base_link">
    <visual>
      <origin xyz="0 0 .3"/>
      <!-- IF user desires visual for base/frame
      <geometry>
        <cylinder length="0.005" radius="0.2"/>
        </geometry>
          <material name="white">
          <color rgba="1 1 1 1"/>
          </material>        -->
  </visual>
  </link>

  <link name="Top_Panel">
    <visual>
      <!--     <origin rpy="0 0 0" xyz="0 0 -1"/>  -->
      <geometry>
        <mesh filename="package://DaVinci_tutorials/intuitiveresearchkit_ros/MTM_CAD_Model/meshes/Top_panel.STL"/>
      </geometry>
      <material name="blue">
        <color rgba="0 0 .8 1"/>
      </material>
    </visual>
    <inertial>
       <mass value="900"/>
       <inertia ixx="90.0" ixy="0.0" ixz="0.0" iyy="90.0" iyz="0.0" izz="90.0"/>
    </inertial> 
  </link>


  <joint name="base_to_top_panel" type="fixed">
    <parent link="base_link"/>
    <child link="Top_Panel"/>
    <origin xyz="0 0 0"/>
  </joint>


  <link name="OutPitch_S">
    <visual>
      <geometry>
        <mesh filename="package://DaVinci_tutorials/intuitiveresearchkit_ros/MTM_CAD_Model/meshes/OutPitch_Shoulder.STL"/>
      </geometry>
    </visual>
    <material name="white">
      <color rgba="1 1 1 1"/>
    </material>
    <inertial>
      <mass value="1000"/>
      <inertia ixx="100.0" ixy="0.0" ixz="0.0" iyy="100.0" iyz="0.0" izz="100.0"/>
    </inertial>
  </link>

  <joint name="Top_panel_to_OutPitchSh" type="revolute">
    <parent link="Top_Panel"/>
    <child link="OutPitch_S"/>
    <origin rpy="0 0 3.14159" xyz="0 0 0"/>
    <axis xyz="0 0 1"/>
    <!--rotates about z axis-->
    <!--limit effort and velocity picked arbitrarily check-->
    <limit effort="1000.0" lower="-.70" upper="2.16" velocity="1000"/>
    <joint_properties damping="0.0" friction="0.0"/>
  </joint>

  <link name="A_Parallel">
    <visual>
      <geometry>
        <mesh filename="package://DaVinci_tutorials/intuitiveresearchkit_ros/MTM_CAD_Model/meshes/ArmParallel.dae"/>
      </geometry>
    </visual>
      <inertial>
      <mass value="900"/>
      <inertia ixx="90.0" ixy="0.0" ixz="0.0" iyy="90.0" iyz="0.0" izz="90.0"/>
    </inertial>
  </link>

  <link name="A_Par_x2">
    <visual>
      <geometry>
        <mesh filename="package://DaVinci_tutorials/intuitiveresearchkit_ros/MTM_CAD_Model/meshes/ArmParallel1.STL"/>
      </geometry>
    </visual>
     <inertial>
      <mass value="500"/>
      <inertia ixx="50.0" ixy="0.0" ixz="0.0" iyy="50.0" iyz="0.0" izz="50.0"/>
    </inertial>
  </link>
  
  <link name="Link_APar">
    <visual>
      <geometry>
        <mesh filename="package://DaVinci_tutorials/intuitiveresearchkit_ros/MTM_CAD_Model/meshes/Link.STL"/>
      </geometry>
    </visual>
     <inertial>
      <mass value="300"/>
      <inertia ixx="30.0" ixy="0.0" ixz="0.0" iyy="30.0" iyz="0.0" izz="30.0"/>
    </inertial>
    </link> 

  <joint name="OutPitchSh_to_AParallel" type="revolute">
    <parent link="OutPitch_S"/>
    <child link="A_Parallel"/>  <!-- xyz= 0 0 -.19037-->
    <origin rpy="1.57 1.57 -1.57" xyz="-0.029 0 -.19037"/>
    <axis xyz="0 0 1"/>
    <!--rotates about  x axis-->
    <!--limit effort and velocity picked arbitrarily check-->
    <limit effort="100.0" lower="-1.14" upper="1.0" velocity="1000"/>
    <joint_properties damping="0.0" friction="0.0"/>
  </joint>

  <joint name="OutPitchSh_to_APar_X2" type="revolute">
    <parent link="OutPitch_S"/>
    <child link="A_Par_x2"/>
    <origin rpy="1.57 0 1.57" xyz=".03537 0 -.19037"/>
    <axis xyz="0 0 1"/>
    <!--rotates about  x axis-->
    <!--limit effort and velocity picked arbitrarily check-->
    <limit effort="100.0" lower="-1.14" upper="1.0" velocity="1000"/>
    <joint_properties damping="0.0" friction="0.0"/>
  </joint>

  
  <joint name="AparX2_to_link" type="revolute">
    <parent link="A_Par_x2"/>
    <child link="Link_APar"/>
    <origin rpy="0 0 0" xyz=".1011 0 0"/>
    <axis xyz="0 0 1"/>
       <!--limit effort and velocity picked arbitrarily check-->
       <!-- Link_APar will not move from its attached link (A_Parx2)-->
    <limit effort="100.0" lower="0" upper="0" velocity="1000"/>
    <joint_properties damping="0.0" friction="0.0"/>
  </joint>


  <link name="A_Bottom">
    <visual>
      <origin xyz="0 0 0"/>
      <geometry>
        <mesh filename="package://DaVinci_tutorials/intuitiveresearchkit_ros/MTM_CAD_Model/meshes/BottomArm.STL"/>
      </geometry>
      <material name="blue">
        <color rgba="0 0 .8 1"/>
      </material>
    </visual>
     <inertial>
      <mass value="800"/>
      <inertia ixx="80.0" ixy="0.0" ixz="0.0" iyy="90.0" iyz="0.0" izz="80.0"/>
    </inertial> 
  </link>

  <joint name="Aparallel_to_Abottom" type="revolute">
    <parent link="A_Parallel"/>
    <child link="A_Bottom"/>  <!-- xyz= -->
    <origin rpy="0 3.14159 0" xyz=".2794 0 0"/>
    <axis xyz="0 0 1"/>
    <!--rotates about x axis-->
    <!--limit effort and velocity picked arbitrarily check-->
    <limit effort="100.0" lower=".33" upper="2.35" velocity="1000"/>
    <joint_properties damping="0.0" friction="0.0"/>
  </joint>


  
  
  <link name="Wrist_Platform">
    <visual>
      <origin xyz="0 0 0" />
      <geometry>
        <mesh filename="package://DaVinci_tutorials/intuitiveresearchkit_ros/MTM_CAD_Model/meshes/WristPlatform.STL"/>
      </geometry>
    </visual>
      <inertial>
      <mass value="300"/>
      <inertia ixx="30.0" ixy="0.0" ixz="0.0" iyy="30.0" iyz="0.0" izz="30.0"/>
    </inertial>
  </link>

  <joint name="ABottom_to_WristPlat" type="revolute">
    <parent link="A_Bottom"/>
    <child link="Wrist_Platform"/>  <!-- -.3048 & -.02746 defined from MTMDaVinci paper and  added -.01 from original to align, -0.02746 defined from CAD file-->
    <origin rpy="3.14 1.57 1.57" xyz="-.3148 -.02646 0"/>
    <axis xyz="0 0 1"/>
    <!--rotates about z axis-->
    <!--limit effort and velocity picked arbitrarily check-->
    <limit effort="100.0" lower="0" upper="3.14159" velocity="1000"/>
    <joint_properties damping="0.0" friction="0.0"/>
  </joint>

  <link name="Wrist_Pitch">
    <visual>        <!-- defined from CAD file (increased in the y dir by .005-->
      <origin xyz="0 -.077 -.068"/>
      <geometry>
        <mesh filename="package://DaVinci_tutorials/intuitiveresearchkit_ros/MTM_CAD_Model/meshes/WristPitch.STL"/>
      </geometry>
      <material name="blue">
        <color rgba="0 0 .8 1"/>
      </material>
    </visual>
     <inertial>
      <mass value="250"/>
      <inertia ixx="25.0" ixy="0.0" ixz="0.0" iyy="25.0" iyz="0.0" izz="25.0"/>
    </inertial>
  </link> 


  <joint name="WristPlat_to_WristPitch" type="revolute">
    <parent link="Wrist_Platform"/>
    <child link="Wrist_Pitch"/>   <!--rpy="1.57 0 3.14159 " the num .072 & .123 are defined from CAD file -->
    <origin rpy="0 0 3.14159" xyz="0 -.072 .123"/>
    <axis xyz="0 1 0"/>
    <!--rotates about x axis-->
    <!--limit effort and velocity picked arbitrarily check-->
    <limit effort="100.0" lower="-1.57" upper="3.14159" velocity="1000"/>
    <joint_properties damping="0.0" friction="0.0"/>
  </joint>

  <!--######### UP-TO -DATE #####################################################3-->
  <!--######### UP-TO -DATE #####################################################3-->
  
  <link name="Wrist_Yaw">
    <visual>
      <origin xyz="0 0 0 "/>
      <material name="white">
        <color rgba="1 1 1 1"/>
      </material>
      <geometry>
        <mesh filename="package://DaVinci_tutorials/intuitiveresearchkit_ros/MTM_CAD_Model/meshes/WristYaw.STL"/>
      </geometry>
    </visual>
     <inertial>
      <mass value="200"/>
      <inertia ixx="20.0" ixy="0.0" ixz="0.0" iyy="20.0" iyz="0.0" izz="20.0"/>
    </inertial>
  </link>

  <joint name="Pitch_to_yaw" type="revolute">
    <parent link="Wrist_Pitch"/>
    <child link="Wrist_Yaw"/>    <!--  defined from CAD file-->
    <origin rpy="0 0 0" xyz="0 -.072 -.055"/>
    <axis xyz="0 0 1"/>
    <!--rotates about z axis-->
    <!--limit effort and velocity picked arbitrarily check-->
    <limit effort="100.0"  lower="-2.60" upper="2.50" velocity="1000"/>
    <joint_properties damping="0.0" friction="0.0"/>
  </joint>

  <link name="Wrist_Roll">
    <visual>
      <geometry>
        <mesh filename="package://DaVinci_tutorials/intuitiveresearchkit_ros/MTM_CAD_Model/meshes/WristRoll.STL"/>
      </geometry>
    </visual>
     <inertial>
      <mass value="140"/>
      <inertia ixx="10.0" ixy="0.0" ixz="0.0" iyy="10.0" iyz="0.0" izz="10.0"/>
    </inertial>
  </link>

  <joint name="Yaw_to_Roll" type="revolute">
    <parent link="Wrist_Yaw"/>
    <child link="Wrist_Roll"/>  <!-- -.039 & .055 defined from CAD file-->
    <origin rpy="-1.57 0 0" xyz="0 -.039 .055"/>
    <axis xyz="0 0 1"/>
    <!--rotates about y axis-->
    <!--limit effort and velocity picked arbitrarily check-->
    <limit effort="100.0" lower="-3.14159" upper="3.14159" velocity="1000"/>
    <joint_properties damping="0.0" friction="0.0"/>
  </joint>
  <!--</gazebo>-->
</robot>
