<?xml version="1.0" encoding="utf-8"?>

<robot name="daVinci">

  <!-- link 0: psm base link -->
  <link name="psm_base_link">
    <visual>
      <origin rpy="1.5708 0 3.1416" xyz="0.039 -0.03888 -0.07879"/>
      <geometry>
        <mesh filename="package://dvrk_model/meshes/psm_base.dae"/>      
      </geometry>
    </visual>
  </link>
  
  <!-- joint 1 -->
  <joint name="outer_yaw_joint" type="revolute">
    <parent link="psm_base_link"/>
    <child link="outer_yaw_link"/>
    <axis xyz="0 0 1"/>
    <origin rpy="1.5708 -1.5708 0" xyz="0.0 0.0 0.0"/>
    <limit lower="-1.5707" upper="1.5707" velocity=".4" effort="1000"/>
  </joint> 
  
  
  <!-- link 1: outer_yaw -->
  <link name="outer_yaw_link">
    <visual>
      <!-- <origin rpy="0 0 -1.5708" xyz="0.0125 0 0.1575"/> -->
      <origin rpy="3.1416 0 1.5708" xyz="0.0125 0 0.1575"/>
      <geometry>
        <mesh filename="package://dvrk_model/meshes/outer_yaw.dae"/>      
      </geometry>
    </visual>
  </link>

  <!-- joint 2-1: outer_pitch_1 -->
  <joint name="outer_pitch_joint_1" type="revolute">
    <parent link="outer_yaw_link"/>
    <child link="outer_pitch_back_link"/>
    <axis xyz="0 0 1"/>
    <origin rpy="-1.5708 -1.5708 0" xyz="0 0.0295 0.1495"/>
    <limit lower="-0.7854" upper="0.7854" velocity=".4" effort="1000"/>
  </joint> 
  
  <!-- link 2: outer_pitch_back -->
  <link name="outer_pitch_back_link">
    <visual>
      <origin rpy="0 0 -0.27129" xyz="0 0 0"/>
      <geometry>
        <mesh filename="package://dvrk_model/meshes/outer_pitch_back.dae"/>      
      </geometry>
    </visual>
  </link>

  <!-- joint 2-2: outer_pitch_2 -->
  <joint name="outer_pitch_joint_2" type="continuous">
    <parent link="outer_yaw_link"/>
    <child link="outer_pitch_front_link"/>
    <axis xyz="0 0 1"/>
    <origin rpy="-1.5708 -1.5708 0" xyz="0 0.0295 0.0595"/>
    <mimic joint="outer_pitch_joint_1" multiplier="1"/>
  </joint>

  <!-- link 2-2: outer_pitch_front -->
  <link name="outer_pitch_front_link">
    <visual>
      <origin rpy="0 0 -0.27129" xyz="0 0 0"/>
      <!-- <origin rpy="0 0 0" xyz="0 0 0"/> -->
      <geometry>
        <mesh filename="package://dvrk_model/meshes/outer_pitch_front.dae"/>      
      </geometry>
    </visual>
  </link>

  <!-- joint 2-3: outer_pitch_3 -->
  <joint name="outer_pitch_joint_3" type="continuous">
    <parent link="outer_pitch_back_link"/>
    <child link="outer_pitch_bottom_link"/>
    <axis xyz="0 0 1"/>
    <origin rpy="0 0 0" xyz="0.04178 0.15007 -0.0137"/>
    <mimic joint="outer_pitch_joint_1" multiplier="-1"/>
  </joint>

  <!-- link 2-3: outer_pitch_bottom -->
  <link name="outer_pitch_bottom_link">
    <visual>
      <origin rpy="0 -1.5708 0" xyz="0.009 0 0"/>
      <geometry>
        <mesh filename="package://dvrk_model/meshes/outer_pitch_bottom.dae"/>      
      </geometry>
    </visual>
  </link>

  <!-- joint 2-4: outer_pitch_4 -->
  <joint name="outer_pitch_joint_4" type="continuous">
    <parent link="outer_pitch_back_link"/>
    <child link="outer_pitch_top_link"/>
    <axis xyz="0 0 1"/>
    <origin rpy="0 0 0" xyz="0.04209 0.18695 -0.02412"/>
    <mimic joint="outer_pitch_joint_1" multiplier="-1"/>
  </joint>

  <!-- link 2-4: outer_pitch_top -->
  <link name="outer_pitch_top_link">
    <visual>
      <origin rpy="0 -1.5708 0" xyz="0.009 0 0"/>
      <geometry>
        <mesh filename="package://dvrk_model/meshes/outer_pitch_top.dae"/>      
      </geometry>
    </visual>
  </link>

  <!-- joint 2-5: outer_pitch_5 -->
  <joint name="outer_pitch_joint_5" type="continuous">
    <parent link="outer_pitch_bottom_link"/>
    <child link="outer_insertion_link"/>
    <axis xyz="0 0 1"/>
    <origin rpy="0 0 0" xyz="-0.520 0 -0.0175"/>
    <mimic joint="outer_pitch_joint_1" multiplier="1"/>
  </joint>

  <!-- link 2-5: outer_insertion -->
  <link name="outer_insertion_link">
    <visual>
      <origin rpy="0 -1.5708 1.5708" xyz="0.02528 0.429 0"/>
      <geometry>
        <mesh filename="package://dvrk_model/meshes/outer_insertion.dae"/>      
      </geometry>
    </visual>
  </link>

  <!-- joint 3: insertion -->
  <joint name="outer_insertion_joint" type="prismatic">
    <parent link="outer_insertion_link"/>
    <child link="tool_main_link"/>
    <axis xyz="0 0 1"/>
    <origin rpy="1.5708 0 0" xyz="-0.0403 0.23622 0"/>
    <limit lower="0" upper="0.240" velocity=".4" effort="1000"/>
  </joint>

  <!-- link 3: tool_main_link -->
  <link name="tool_main_link">
    <visual>
      <origin rpy="0 0 1.5708" xyz="0 0 0"/>
      <geometry>
        <mesh filename="package://dvrk_model/meshes/tool_main.dae"/>      
      </geometry>
    </visual>
  </link>
  
  <!-- joint 4-1: Outer Roll -->
  <joint name="outer_roll_joint" type="revolute">
    <parent link="tool_main_link"/>
    <child link="tool_wrist_link"/>
    <axis xyz="0 0 1"/>
    <origin rpy="0 0 0" xyz="0 0 0.36680"/>
    <limit lower="-2.2689" upper="2.2689" velocity=".4" effort="1000"/>
  </joint>

  <!-- link 4-1: tool_main_link -->
  <link name="tool_wrist_link">
    <visual>
      <origin rpy="0 0 1.5708" xyz="0 0 0"/>
      <geometry>
        <mesh filename="package://dvrk_model/meshes/tool_wrist_link.dae"/>      
      </geometry>
    </visual>
  </link>

  <!-- joint 4-1: Outer Roll shaft -->
  <joint name="outer_roll_shaft_joint" type="fixed">
    <parent link="tool_wrist_link"/>
    <child link="tool_wrist_shaft_link"/>
    <axis xyz="0 0 1"/>
    <origin rpy="0 0 0" xyz="0 0 0.0091"/>
  </joint>

  <!-- link 4-1: tool_wrist_shaft_link -->
  <link name="tool_wrist_shaft_link">
    <visual>
      <origin rpy="1.5708 0 0" xyz="0 0.00401 0"/>
      <geometry>
        <mesh filename="package://dvrk_model/meshes/tool_wrist_shaft_link.dae"/> 
      </geometry>
    </visual>
  </link>

  <!-- joint 5: Outer wrist pitch joint -->
  <joint name="outer_wrist_pitch_joint" type="revolute">
    <parent link="tool_wrist_shaft_link"/>
    <child link="tool_wrist_sca_link"/>
    <axis xyz="0 0 1"/>
    <origin rpy="-1.5708 -1.5708 0" xyz="0 0 0"/>
    <limit lower="-1.5707" upper="1.5707" velocity=".4" effort="1000"/>
  </joint>

  <!-- link 5: tool_wrist_sca_link -->
  <link name="tool_wrist_sca_link">
    <visual>
      <!-- <origin rpy="0 3.1416 0" xyz="0 0 0"/> -->
      <origin rpy="1.5708 3.1416 0" xyz="0.0051 0.0032 0"/>
      <geometry>
        <mesh filename="package://dvrk_model/meshes/tool_wrist_sca_link.dae"/> 
      </geometry>
    </visual>
  </link>

  <!-- joint 5-2: Outer wristyaw joint -->
  <joint name="outer_wrist_yaw_joint" type="revolute">
    <parent link="tool_wrist_sca_link"/>
    <child link="tool_wrist_sca_shaft_link"/>
    <axis xyz="0 0 1"/>
    <origin rpy="-1.5708 -1.5708 0" xyz="0.0089 0 0"/>
    <!-- +/- 80 deg -->
    <limit lower="-1.3963" upper="1.3963" velocity=".4" effort="1000"/>
  </joint>

  <!-- link 5-2: tool_wrist_sca_shaft_link -->
  <link name="tool_wrist_sca_shaft_link">
    <visual>
      <origin rpy="0 0 0" xyz="0 0 -0.0025"/>
      <geometry>
        <mesh filename="package://dvrk_model/meshes/tool_wrist_sca_shaft_link.dae"/> 
      </geometry>
    </visual>
  </link>
  
  <!-- joint 6-1: Outer open angle 1  -->
  <joint name="outer_wrist_open_angle_joint_1" type="revolute">
    <parent link="tool_wrist_sca_shaft_link"/>
    <child link="tool_wrist_sca_ee_link_1"/>
    <axis xyz="0 0 1"/>
    <origin rpy="0 0 0" xyz="0 0 0"/>
    <!-- <origin rpy="-1.5708 -1.5708 0" xyz="0 0 0"/> -->
    <limit lower="0" upper="1.5707" velocity=".4" effort="1000"/>
  </joint>

  <!-- link 6-1: Outer open angle link 1 -->
  <link name="tool_wrist_sca_ee_link_1">
    <visual>
      <origin rpy="0 0 0" xyz="0 0 0"/>
      <geometry>
        <mesh filename="package://dvrk_model/meshes/tool_wrist_sca_link_2.dae"/>
      </geometry>
    </visual>
  </link>

  <!-- joint 6-2: Outer open angle 2   -->
  <joint name="outer_wrist_open_angle_joint_2" type="revolute">
    <parent link="tool_wrist_sca_shaft_link"/>
    <child link="tool_wrist_sca_ee_link_2"/>
    <axis xyz="0 0 1"/>
    <origin rpy="0 0 0" xyz="0 0 0"/>
    <limit lower="-1.5707" upper="1.5707" velocity=".4" effort="1000"/>
    <mimic joint="outer_wrist_open_angle_joint_1" multiplier="-1"/>
  </joint>

  <!-- link 6-2: Outer open angle link 2 -->
  <link name="tool_wrist_sca_ee_link_2">
    <visual>
      <origin rpy="0 3.1516 0" xyz="0 0 0"/>
      <geometry>
        <mesh filename="package://dvrk_model/meshes/tool_wrist_sca_link_2.dae"/>
      </geometry>
    </visual>
  </link>


  
</robot>